<?xml version="1.0" encoding="utf-8"?><testsuites><testsuite errors="1" failures="0" hostname="E0004929GM" name="pytest" skipped="0" tests="3" time="195.983" timestamp="2021-07-21T15:06:33.916886"><testcase classname="test_dir.test_a_kernel.TestKernel" name="test_sanity_2" time="129.369" /><testcase classname="test_dir.test_a_kernel.TestKernel" name="test_sanity_8" time="23.339" /><testcase time="16.877" /><testcase classname="pytest" name="internal" time="0.000"><error message="internal error">Traceback (most recent call last):
  File "C:\Python_tools\sanity_ld60_mini\venv\lib\site-packages\_pytest\main.py", line 269, in wrap_session
    session.exitstatus = doit(config, session) or 0
  File "C:\Python_tools\sanity_ld60_mini\venv\lib\site-packages\_pytest\main.py", line 323, in _main
    config.hook.pytest_runtestloop(session=session)
  File "C:\Python_tools\sanity_ld60_mini\venv\lib\site-packages\pluggy\hooks.py", line 286, in __call__
    return self._hookexec(self, self.get_hookimpls(), kwargs)
  File "C:\Python_tools\sanity_ld60_mini\venv\lib\site-packages\pluggy\manager.py", line 93, in _hookexec
    return self._inner_hookexec(hook, methods, kwargs)
  File "C:\Python_tools\sanity_ld60_mini\venv\lib\site-packages\pluggy\manager.py", line 87, in &lt;lambda&gt;
    firstresult=hook.spec.opts.get("firstresult") if hook.spec else False,
  File "C:\Python_tools\sanity_ld60_mini\venv\lib\site-packages\pluggy\callers.py", line 208, in _multicall
    return outcome.get_result()
  File "C:\Python_tools\sanity_ld60_mini\venv\lib\site-packages\pluggy\callers.py", line 80, in get_result
    raise ex[1].with_traceback(ex[2])
  File "C:\Python_tools\sanity_ld60_mini\venv\lib\site-packages\pluggy\callers.py", line 187, in _multicall
    res = hook_impl.function(*args)
  File "C:\Python_tools\sanity_ld60_mini\venv\lib\site-packages\_pytest\main.py", line 348, in pytest_runtestloop
    item.config.hook.pytest_runtest_protocol(item=item, nextitem=nextitem)
  File "C:\Python_tools\sanity_ld60_mini\venv\lib\site-packages\pluggy\hooks.py", line 286, in __call__
    return self._hookexec(self, self.get_hookimpls(), kwargs)
  File "C:\Python_tools\sanity_ld60_mini\venv\lib\site-packages\pluggy\manager.py", line 93, in _hookexec
    return self._inner_hookexec(hook, methods, kwargs)
  File "C:\Python_tools\sanity_ld60_mini\venv\lib\site-packages\pluggy\manager.py", line 87, in &lt;lambda&gt;
    firstresult=hook.spec.opts.get("firstresult") if hook.spec else False,
  File "C:\Python_tools\sanity_ld60_mini\venv\lib\site-packages\pluggy\callers.py", line 208, in _multicall
    return outcome.get_result()
  File "C:\Python_tools\sanity_ld60_mini\venv\lib\site-packages\pluggy\callers.py", line 80, in get_result
    raise ex[1].with_traceback(ex[2])
  File "C:\Python_tools\sanity_ld60_mini\venv\lib\site-packages\pluggy\callers.py", line 187, in _multicall
    res = hook_impl.function(*args)
  File "C:\Python_tools\sanity_ld60_mini\venv\lib\site-packages\_pytest\runner.py", line 109, in pytest_runtest_protocol
    runtestprotocol(item, nextitem=nextitem)
  File "C:\Python_tools\sanity_ld60_mini\venv\lib\site-packages\_pytest\runner.py", line 126, in runtestprotocol
    reports.append(call_and_report(item, "call", log))
  File "C:\Python_tools\sanity_ld60_mini\venv\lib\site-packages\_pytest\runner.py", line 217, in call_and_report
    report: TestReport = hook.pytest_runtest_makereport(item=item, call=call)
  File "C:\Python_tools\sanity_ld60_mini\venv\lib\site-packages\pluggy\hooks.py", line 286, in __call__
    return self._hookexec(self, self.get_hookimpls(), kwargs)
  File "C:\Python_tools\sanity_ld60_mini\venv\lib\site-packages\pluggy\manager.py", line 93, in _hookexec
    return self._inner_hookexec(hook, methods, kwargs)
  File "C:\Python_tools\sanity_ld60_mini\venv\lib\site-packages\pluggy\manager.py", line 87, in &lt;lambda&gt;
    firstresult=hook.spec.opts.get("firstresult") if hook.spec else False,
  File "C:\Python_tools\sanity_ld60_mini\venv\lib\site-packages\pluggy\callers.py", line 203, in _multicall
    gen.send(outcome)
  File "C:\Python_tools\sanity_ld60_mini\conftest.py", line 86, in pytest_runtest_makereport
    capture_screenshots(case_name)
  File "C:\Python_tools\sanity_ld60_mini\conftest.py", line 134, in capture_screenshots
    driver.get_screenshot_as_file(image_dir)
  File "C:\Python_tools\sanity_ld60_mini\venv\lib\site-packages\selenium\webdriver\remote\webdriver.py", line 1032, in get_screenshot_as_file
    png = self.get_screenshot_as_png()
  File "C:\Python_tools\sanity_ld60_mini\venv\lib\site-packages\selenium\webdriver\remote\webdriver.py", line 1064, in get_screenshot_as_png
    return base64.b64decode(self.get_screenshot_as_base64().encode('ascii'))
  File "C:\Python_tools\sanity_ld60_mini\venv\lib\site-packages\selenium\webdriver\remote\webdriver.py", line 1074, in get_screenshot_as_base64
    return self.execute(Command.SCREENSHOT)['value']
  File "C:\Python_tools\sanity_ld60_mini\venv\lib\site-packages\selenium\webdriver\remote\webdriver.py", line 321, in execute
    self.error_handler.check_response(response)
  File "C:\Python_tools\sanity_ld60_mini\venv\lib\site-packages\appium\webdriver\errorhandler.py", line 31, in check_response
    raise wde
  File "C:\Python_tools\sanity_ld60_mini\venv\lib\site-packages\appium\webdriver\errorhandler.py", line 26, in check_response
    super().check_response(response)
  File "C:\Python_tools\sanity_ld60_mini\venv\lib\site-packages\selenium\webdriver\remote\errorhandler.py", line 242, in check_response
    raise exception_class(message, screen, stacktrace)
selenium.common.exceptions.WebDriverException: Message: An unknown server-side error occurred while processing the command. Original error: Could not proxy command to the remote server. Original error: connect ECONNREFUSED 127.0.0.1:8200</error></testcase></testsuite></testsuites>